The ``--output_space`` option has been deprecated in version 1.4.0. Your selection of spaces "T1w, template, fsaverage5, fsnative" will be inserted at the front of the ``--output-spaces`` argument list. Please update your scripts to use ``--output-spaces``.
/usr/local/miniconda/lib/python3.7/site-packages/bids/layout/layout.py:62: UserWarning: Accessing entities as attributes is deprecated as of 0.7. Please use the .entities dictionary instead (i.e., .entities['suffix'] instead of .suffix.
  % (attr, attr))
/usr/local/miniconda/lib/python3.7/site-packages/bids/layout/layout.py:62: UserWarning: Accessing entities as attributes is deprecated as of 0.7. Please use the .entities dictionary instead (i.e., .entities['suffix'] instead of .suffix.
  % (attr, attr))
/usr/local/miniconda/lib/python3.7/site-packages/bids/layout/layout.py:62: UserWarning: Accessing entities as attributes is deprecated as of 0.7. Please use the .entities dictionary instead (i.e., .entities['suffix'] instead of .suffix.
  % (attr, attr))
/usr/local/miniconda/lib/python3.7/site-packages/bids/layout/layout.py:62: UserWarning: Accessing entities as attributes is deprecated as of 0.7. Please use the .entities dictionary instead (i.e., .entities['suffix'] instead of .suffix.
  % (attr, attr))
/usr/local/miniconda/lib/python3.7/site-packages/bids/layout/layout.py:62: UserWarning: Accessing entities as attributes is deprecated as of 0.7. Please use the .entities dictionary instead (i.e., .entities['suffix'] instead of .suffix.
  % (attr, attr))
/usr/local/miniconda/lib/python3.7/site-packages/bids/layout/layout.py:62: UserWarning: Accessing entities as attributes is deprecated as of 0.7. Please use the .entities dictionary instead (i.e., .entities['suffix'] instead of .suffix.
  % (attr, attr))
/usr/local/miniconda/lib/python3.7/site-packages/bids/layout/layout.py:62: UserWarning: Accessing entities as attributes is deprecated as of 0.7. Please use the .entities dictionary instead (i.e., .entities['suffix'] instead of .suffix.
  % (attr, attr))
/usr/local/miniconda/lib/python3.7/site-packages/bids/layout/layout.py:62: UserWarning: Accessing entities as attributes is deprecated as of 0.7. Please use the .entities dictionary instead (i.e., .entities['suffix'] instead of .suffix.
  % (attr, attr))
/usr/local/miniconda/lib/python3.7/site-packages/bids/layout/layout.py:62: UserWarning: Accessing entities as attributes is deprecated as of 0.7. Please use the .entities dictionary instead (i.e., .entities['suffix'] instead of .suffix.
  % (attr, attr))
/usr/local/miniconda/lib/python3.7/site-packages/bids/layout/layout.py:62: UserWarning: Accessing entities as attributes is deprecated as of 0.7. Please use the .entities dictionary instead (i.e., .entities['suffix'] instead of .suffix.
  % (attr, attr))
/usr/local/miniconda/lib/python3.7/site-packages/bids/layout/layout.py:62: UserWarning: Accessing entities as attributes is deprecated as of 0.7. Please use the .entities dictionary instead (i.e., .entities['suffix'] instead of .suffix.
  % (attr, attr))
/usr/local/miniconda/lib/python3.7/site-packages/bids/layout/layout.py:62: UserWarning: Accessing entities as attributes is deprecated as of 0.7. Please use the .entities dictionary instead (i.e., .entities['suffix'] instead of .suffix.
  % (attr, attr))
exception calling callback for <Future at 0x2aaad27e6320 state=finished raised OSError>
concurrent.futures.process._RemoteTraceback: 
"""
Traceback (most recent call last):
  File "/usr/local/miniconda/lib/python3.7/site-packages/nipype/pipeline/plugins/multiproc.py", line 69, in run_node
    result['result'] = node.run(updatehash=updatehash)
  File "/usr/local/miniconda/lib/python3.7/site-packages/nipype/pipeline/engine/nodes.py", line 487, in run
    self, report_type='postexec', is_mapnode=isinstance(self, MapNode))
  File "/usr/local/miniconda/lib/python3.7/site-packages/nipype/pipeline/engine/utils.py", line 149, in write_report
    result = node.result  # Locally cache result
  File "/usr/local/miniconda/lib/python3.7/site-packages/nipype/pipeline/engine/nodes.py", line 197, in result
    return _load_resultfile(self.output_dir(), self.name)[0]
  File "/usr/local/miniconda/lib/python3.7/site-packages/nipype/pipeline/engine/utils.py", line 359, in load_resultfile
    basedir=path).items()):
  File "/usr/local/miniconda/lib/python3.7/site-packages/nipype/pipeline/engine/utils.py", line 478, in modify_paths
    val, relative=relative, basedir=basedir)
  File "/usr/local/miniconda/lib/python3.7/site-packages/nipype/pipeline/engine/utils.py", line 484, in modify_paths
    modify_paths(val, relative=relative, basedir=basedir))
  File "/usr/local/miniconda/lib/python3.7/site-packages/nipype/pipeline/engine/utils.py", line 498, in modify_paths
    raise IOError('File %s not found' % out)
OSError: File /projects/adapt_lab/shared/TPOT/bids_data/derivatives/working/fmriprep_wf/single_subject_TPOT004_wf/func_preproc_ses_1_task_affect_acq_1_wf/func_derivatives_wf/raw_sources/sub-TPOT004/ses-1/func/sub-TPOT004_ses-1_task-affect_acq-1_bold.nii.gz not found

During handling of the above exception, another exception occurred:

Traceback (most recent call last):
  File "/usr/local/miniconda/lib/python3.7/concurrent/futures/process.py", line 232, in _process_worker
    r = call_item.fn(*call_item.args, **call_item.kwargs)
  File "/usr/local/miniconda/lib/python3.7/site-packages/nipype/pipeline/plugins/multiproc.py", line 72, in run_node
    result['result'] = node.result
  File "/usr/local/miniconda/lib/python3.7/site-packages/nipype/pipeline/engine/nodes.py", line 197, in result
    return _load_resultfile(self.output_dir(), self.name)[0]
  File "/usr/local/miniconda/lib/python3.7/site-packages/nipype/pipeline/engine/utils.py", line 359, in load_resultfile
    basedir=path).items()):
  File "/usr/local/miniconda/lib/python3.7/site-packages/nipype/pipeline/engine/utils.py", line 478, in modify_paths
    val, relative=relative, basedir=basedir)
  File "/usr/local/miniconda/lib/python3.7/site-packages/nipype/pipeline/engine/utils.py", line 484, in modify_paths
    modify_paths(val, relative=relative, basedir=basedir))
  File "/usr/local/miniconda/lib/python3.7/site-packages/nipype/pipeline/engine/utils.py", line 498, in modify_paths
    raise IOError('File %s not found' % out)
OSError: File /projects/adapt_lab/shared/TPOT/bids_data/derivatives/working/fmriprep_wf/single_subject_TPOT004_wf/func_preproc_ses_1_task_affect_acq_1_wf/func_derivatives_wf/raw_sources/sub-TPOT004/ses-1/func/sub-TPOT004_ses-1_task-affect_acq-1_bold.nii.gz not found
"""

The above exception was the direct cause of the following exception:

Traceback (most recent call last):
  File "/usr/local/miniconda/lib/python3.7/concurrent/futures/_base.py", line 324, in _invoke_callbacks
    callback(self)
  File "/usr/local/miniconda/lib/python3.7/site-packages/nipype/pipeline/plugins/multiproc.py", line 151, in _async_callback
    result = args.result()
  File "/usr/local/miniconda/lib/python3.7/concurrent/futures/_base.py", line 425, in result
    return self.__get_result()
  File "/usr/local/miniconda/lib/python3.7/concurrent/futures/_base.py", line 384, in __get_result
    raise self._exception
OSError: File /projects/adapt_lab/shared/TPOT/bids_data/derivatives/working/fmriprep_wf/single_subject_TPOT004_wf/func_preproc_ses_1_task_affect_acq_1_wf/func_derivatives_wf/raw_sources/sub-TPOT004/ses-1/func/sub-TPOT004_ses-1_task-affect_acq-1_bold.nii.gz not found
exception calling callback for <Future at 0x2aaad3d907b8 state=finished raised OSError>
concurrent.futures.process._RemoteTraceback: 
"""
Traceback (most recent call last):
  File "/usr/local/miniconda/lib/python3.7/site-packages/nipype/pipeline/plugins/multiproc.py", line 69, in run_node
    result['result'] = node.run(updatehash=updatehash)
  File "/usr/local/miniconda/lib/python3.7/site-packages/nipype/pipeline/engine/nodes.py", line 487, in run
    self, report_type='postexec', is_mapnode=isinstance(self, MapNode))
  File "/usr/local/miniconda/lib/python3.7/site-packages/nipype/pipeline/engine/utils.py", line 149, in write_report
    result = node.result  # Locally cache result
  File "/usr/local/miniconda/lib/python3.7/site-packages/nipype/pipeline/engine/nodes.py", line 197, in result
    return _load_resultfile(self.output_dir(), self.name)[0]
  File "/usr/local/miniconda/lib/python3.7/site-packages/nipype/pipeline/engine/utils.py", line 359, in load_resultfile
    basedir=path).items()):
  File "/usr/local/miniconda/lib/python3.7/site-packages/nipype/pipeline/engine/utils.py", line 478, in modify_paths
    val, relative=relative, basedir=basedir)
  File "/usr/local/miniconda/lib/python3.7/site-packages/nipype/pipeline/engine/utils.py", line 484, in modify_paths
    modify_paths(val, relative=relative, basedir=basedir))
  File "/usr/local/miniconda/lib/python3.7/site-packages/nipype/pipeline/engine/utils.py", line 498, in modify_paths
    raise IOError('File %s not found' % out)
OSError: File /projects/adapt_lab/shared/TPOT/bids_data/derivatives/working/fmriprep_wf/single_subject_TPOT004_wf/func_preproc_ses_1_task_affect_acq_2_wf/func_derivatives_wf/raw_sources/sub-TPOT004/ses-1/func/sub-TPOT004_ses-1_task-affect_acq-2_bold.nii.gz not found

During handling of the above exception, another exception occurred:

Traceback (most recent call last):
  File "/usr/local/miniconda/lib/python3.7/concurrent/futures/process.py", line 232, in _process_worker
    r = call_item.fn(*call_item.args, **call_item.kwargs)
  File "/usr/local/miniconda/lib/python3.7/site-packages/nipype/pipeline/plugins/multiproc.py", line 72, in run_node
    result['result'] = node.result
  File "/usr/local/miniconda/lib/python3.7/site-packages/nipype/pipeline/engine/nodes.py", line 197, in result
    return _load_resultfile(self.output_dir(), self.name)[0]
  File "/usr/local/miniconda/lib/python3.7/site-packages/nipype/pipeline/engine/utils.py", line 359, in load_resultfile
    basedir=path).items()):
  File "/usr/local/miniconda/lib/python3.7/site-packages/nipype/pipeline/engine/utils.py", line 478, in modify_paths
    val, relative=relative, basedir=basedir)
  File "/usr/local/miniconda/lib/python3.7/site-packages/nipype/pipeline/engine/utils.py", line 484, in modify_paths
    modify_paths(val, relative=relative, basedir=basedir))
  File "/usr/local/miniconda/lib/python3.7/site-packages/nipype/pipeline/engine/utils.py", line 498, in modify_paths
    raise IOError('File %s not found' % out)
OSError: File /projects/adapt_lab/shared/TPOT/bids_data/derivatives/working/fmriprep_wf/single_subject_TPOT004_wf/func_preproc_ses_1_task_affect_acq_2_wf/func_derivatives_wf/raw_sources/sub-TPOT004/ses-1/func/sub-TPOT004_ses-1_task-affect_acq-2_bold.nii.gz not found
"""

The above exception was the direct cause of the following exception:

Traceback (most recent call last):
  File "/usr/local/miniconda/lib/python3.7/concurrent/futures/_base.py", line 324, in _invoke_callbacks
    callback(self)
  File "/usr/local/miniconda/lib/python3.7/site-packages/nipype/pipeline/plugins/multiproc.py", line 151, in _async_callback
    result = args.result()
  File "/usr/local/miniconda/lib/python3.7/concurrent/futures/_base.py", line 425, in result
    return self.__get_result()
  File "/usr/local/miniconda/lib/python3.7/concurrent/futures/_base.py", line 384, in __get_result
    raise self._exception
OSError: File /projects/adapt_lab/shared/TPOT/bids_data/derivatives/working/fmriprep_wf/single_subject_TPOT004_wf/func_preproc_ses_1_task_affect_acq_2_wf/func_derivatives_wf/raw_sources/sub-TPOT004/ses-1/func/sub-TPOT004_ses-1_task-affect_acq-2_bold.nii.gz not found
slurmstepd: error: *** JOB 9546177 ON n084 CANCELLED AT 2019-07-07T18:22:58 DUE TO TIME LIMIT ***
