The ``--output_space`` option has been deprecated in version 1.4.0. Your selection of spaces "T1w, template, fsaverage5, fsnative" will be inserted at the front of the ``--output-spaces`` argument list. Please update your scripts to use ``--output-spaces``.
/usr/local/miniconda/lib/python3.7/site-packages/bids/layout/layout.py:62: UserWarning: Accessing entities as attributes is deprecated as of 0.7. Please use the .entities dictionary instead (i.e., .entities['suffix'] instead of .suffix.
  % (attr, attr))
/usr/local/miniconda/lib/python3.7/site-packages/bids/layout/layout.py:62: UserWarning: Accessing entities as attributes is deprecated as of 0.7. Please use the .entities dictionary instead (i.e., .entities['suffix'] instead of .suffix.
  % (attr, attr))
/usr/local/miniconda/lib/python3.7/site-packages/bids/layout/layout.py:62: UserWarning: Accessing entities as attributes is deprecated as of 0.7. Please use the .entities dictionary instead (i.e., .entities['suffix'] instead of .suffix.
  % (attr, attr))
/usr/local/miniconda/lib/python3.7/site-packages/bids/layout/layout.py:62: UserWarning: Accessing entities as attributes is deprecated as of 0.7. Please use the .entities dictionary instead (i.e., .entities['suffix'] instead of .suffix.
  % (attr, attr))
/usr/local/miniconda/lib/python3.7/site-packages/bids/layout/layout.py:62: UserWarning: Accessing entities as attributes is deprecated as of 0.7. Please use the .entities dictionary instead (i.e., .entities['suffix'] instead of .suffix.
  % (attr, attr))
/usr/local/miniconda/lib/python3.7/site-packages/bids/layout/layout.py:62: UserWarning: Accessing entities as attributes is deprecated as of 0.7. Please use the .entities dictionary instead (i.e., .entities['suffix'] instead of .suffix.
  % (attr, attr))
/usr/local/miniconda/lib/python3.7/site-packages/bids/layout/layout.py:62: UserWarning: Accessing entities as attributes is deprecated as of 0.7. Please use the .entities dictionary instead (i.e., .entities['suffix'] instead of .suffix.
  % (attr, attr))
/usr/local/miniconda/lib/python3.7/site-packages/bids/layout/layout.py:62: UserWarning: Accessing entities as attributes is deprecated as of 0.7. Please use the .entities dictionary instead (i.e., .entities['suffix'] instead of .suffix.
  % (attr, attr))
/usr/local/miniconda/lib/python3.7/site-packages/bids/layout/layout.py:62: UserWarning: Accessing entities as attributes is deprecated as of 0.7. Please use the .entities dictionary instead (i.e., .entities['suffix'] instead of .suffix.
  % (attr, attr))
/usr/local/miniconda/lib/python3.7/site-packages/bids/layout/layout.py:62: UserWarning: Accessing entities as attributes is deprecated as of 0.7. Please use the .entities dictionary instead (i.e., .entities['suffix'] instead of .suffix.
  % (attr, attr))
/usr/local/miniconda/lib/python3.7/site-packages/bids/layout/layout.py:62: UserWarning: Accessing entities as attributes is deprecated as of 0.7. Please use the .entities dictionary instead (i.e., .entities['suffix'] instead of .suffix.
  % (attr, attr))
/usr/local/miniconda/lib/python3.7/site-packages/bids/layout/layout.py:62: UserWarning: Accessing entities as attributes is deprecated as of 0.7. Please use the .entities dictionary instead (i.e., .entities['suffix'] instead of .suffix.
  % (attr, attr))
/usr/local/miniconda/lib/python3.7/site-packages/bids/layout/layout.py:62: UserWarning: Accessing entities as attributes is deprecated as of 0.7. Please use the .entities dictionary instead (i.e., .entities['suffix'] instead of .suffix.
  % (attr, attr))
/usr/local/miniconda/lib/python3.7/site-packages/bids/layout/layout.py:62: UserWarning: Accessing entities as attributes is deprecated as of 0.7. Please use the .entities dictionary instead (i.e., .entities['suffix'] instead of .suffix.
  % (attr, attr))
/usr/local/miniconda/lib/python3.7/site-packages/bids/layout/layout.py:62: UserWarning: Accessing entities as attributes is deprecated as of 0.7. Please use the .entities dictionary instead (i.e., .entities['suffix'] instead of .suffix.
  % (attr, attr))
/usr/local/miniconda/lib/python3.7/site-packages/bids/layout/layout.py:62: UserWarning: Accessing entities as attributes is deprecated as of 0.7. Please use the .entities dictionary instead (i.e., .entities['suffix'] instead of .suffix.
  % (attr, attr))
/usr/local/miniconda/lib/python3.7/site-packages/bids/layout/layout.py:62: UserWarning: Accessing entities as attributes is deprecated as of 0.7. Please use the .entities dictionary instead (i.e., .entities['suffix'] instead of .suffix.
  % (attr, attr))
/usr/local/miniconda/lib/python3.7/site-packages/bids/layout/layout.py:62: UserWarning: Accessing entities as attributes is deprecated as of 0.7. Please use the .entities dictionary instead (i.e., .entities['suffix'] instead of .suffix.
  % (attr, attr))
Traceback (most recent call last):
  File "/usr/local/miniconda/bin/fmriprep", line 10, in <module>
    sys.exit(main())
  File "/usr/local/miniconda/lib/python3.7/site-packages/fmriprep/cli/run.py", line 359, in main
    fmriprep_wf.write_graph(graph2use="colored", format='svg', simple_form=True)
  File "/usr/local/miniconda/lib/python3.7/site-packages/nipype/pipeline/engine/workflows.py", line 431, in write_graph
    outfname = format_dot(dotfilename, format=format)
  File "/usr/local/miniconda/lib/python3.7/site-packages/nipype/pipeline/engine/utils.py", line 1398, in format_dot
    formatted_dot, _ = _run_dot(dotfilename, format_ext=format)
  File "/usr/local/miniconda/lib/python3.7/site-packages/nipype/pipeline/engine/utils.py", line 1415, in _run_dot
    resource_monitor=False).run()
  File "/usr/local/miniconda/lib/python3.7/site-packages/nipype/interfaces/base/core.py", line 375, in run
    runtime = self._run_interface(runtime)
  File "/usr/local/miniconda/lib/python3.7/site-packages/nipype/interfaces/base/core.py", line 758, in _run_interface
    self.raise_exception(runtime)
  File "/usr/local/miniconda/lib/python3.7/site-packages/nipype/interfaces/base/core.py", line 695, in raise_exception
    ).format(**runtime.dictcopy()))
RuntimeError: Command:
dot -Tsvg -o"/projects/adapt_lab/shared/TPOT/bids_data/derivatives/working/fmriprep_wf/graph.svg" "/projects/adapt_lab/shared/TPOT/bids_data/derivatives/working/fmriprep_wf/graph.dot"
Standard output:

Standard error:
Error: /projects/adapt_lab/shared/TPOT/bids_data/derivatives/working/fmriprep_wf/graph.dot: syntax error in line 3961 near '_wf_outputnode'
Return code: 1
Sentry is attempting to send 0 pending error messages
Waiting up to 2.0 seconds
Press Ctrl-C to quit
The ``--output_space`` option has been deprecated in version 1.4.0. Your selection of spaces "T1w, template, fsaverage5, fsnative" will be inserted at the front of the ``--output-spaces`` argument list. Please update your scripts to use ``--output-spaces``.
/usr/local/miniconda/lib/python3.7/site-packages/bids/layout/layout.py:62: UserWarning: Accessing entities as attributes is deprecated as of 0.7. Please use the .entities dictionary instead (i.e., .entities['suffix'] instead of .suffix.
  % (attr, attr))
/usr/local/miniconda/lib/python3.7/site-packages/bids/layout/layout.py:62: UserWarning: Accessing entities as attributes is deprecated as of 0.7. Please use the .entities dictionary instead (i.e., .entities['suffix'] instead of .suffix.
  % (attr, attr))
/usr/local/miniconda/lib/python3.7/site-packages/bids/layout/layout.py:62: UserWarning: Accessing entities as attributes is deprecated as of 0.7. Please use the .entities dictionary instead (i.e., .entities['suffix'] instead of .suffix.
  % (attr, attr))
/usr/local/miniconda/lib/python3.7/site-packages/bids/layout/layout.py:62: UserWarning: Accessing entities as attributes is deprecated as of 0.7. Please use the .entities dictionary instead (i.e., .entities['suffix'] instead of .suffix.
  % (attr, attr))
/usr/local/miniconda/lib/python3.7/site-packages/bids/layout/layout.py:62: UserWarning: Accessing entities as attributes is deprecated as of 0.7. Please use the .entities dictionary instead (i.e., .entities['suffix'] instead of .suffix.
  % (attr, attr))
/usr/local/miniconda/lib/python3.7/site-packages/bids/layout/layout.py:62: UserWarning: Accessing entities as attributes is deprecated as of 0.7. Please use the .entities dictionary instead (i.e., .entities['suffix'] instead of .suffix.
  % (attr, attr))
exception calling callback for <Future at 0x2aaad2924898 state=finished raised OSError>
concurrent.futures.process._RemoteTraceback: 
"""
Traceback (most recent call last):
  File "/usr/local/miniconda/lib/python3.7/site-packages/nipype/pipeline/plugins/multiproc.py", line 69, in run_node
    result['result'] = node.run(updatehash=updatehash)
  File "/usr/local/miniconda/lib/python3.7/site-packages/nipype/pipeline/engine/nodes.py", line 487, in run
    self, report_type='postexec', is_mapnode=isinstance(self, MapNode))
  File "/usr/local/miniconda/lib/python3.7/site-packages/nipype/pipeline/engine/utils.py", line 149, in write_report
    result = node.result  # Locally cache result
  File "/usr/local/miniconda/lib/python3.7/site-packages/nipype/pipeline/engine/nodes.py", line 197, in result
    return _load_resultfile(self.output_dir(), self.name)[0]
  File "/usr/local/miniconda/lib/python3.7/site-packages/nipype/pipeline/engine/utils.py", line 359, in load_resultfile
    basedir=path).items()):
  File "/usr/local/miniconda/lib/python3.7/site-packages/nipype/pipeline/engine/utils.py", line 478, in modify_paths
    val, relative=relative, basedir=basedir)
  File "/usr/local/miniconda/lib/python3.7/site-packages/nipype/pipeline/engine/utils.py", line 484, in modify_paths
    modify_paths(val, relative=relative, basedir=basedir))
  File "/usr/local/miniconda/lib/python3.7/site-packages/nipype/pipeline/engine/utils.py", line 498, in modify_paths
    raise IOError('File %s not found' % out)
OSError: File /projects/adapt_lab/shared/TPOT/bids_data/derivatives/working/fmriprep_wf/single_subject_TPOT025_wf/func_preproc_ses_1_task_video_wf/func_derivatives_wf/raw_sources/sub-TPOT025/ses-1/func/sub-TPOT025_ses-1_task-video_bold.nii.gz not found

During handling of the above exception, another exception occurred:

Traceback (most recent call last):
  File "/usr/local/miniconda/lib/python3.7/concurrent/futures/process.py", line 232, in _process_worker
    r = call_item.fn(*call_item.args, **call_item.kwargs)
  File "/usr/local/miniconda/lib/python3.7/site-packages/nipype/pipeline/plugins/multiproc.py", line 72, in run_node
    result['result'] = node.result
  File "/usr/local/miniconda/lib/python3.7/site-packages/nipype/pipeline/engine/nodes.py", line 197, in result
    return _load_resultfile(self.output_dir(), self.name)[0]
  File "/usr/local/miniconda/lib/python3.7/site-packages/nipype/pipeline/engine/utils.py", line 359, in load_resultfile
    basedir=path).items()):
  File "/usr/local/miniconda/lib/python3.7/site-packages/nipype/pipeline/engine/utils.py", line 478, in modify_paths
    val, relative=relative, basedir=basedir)
  File "/usr/local/miniconda/lib/python3.7/site-packages/nipype/pipeline/engine/utils.py", line 484, in modify_paths
    modify_paths(val, relative=relative, basedir=basedir))
  File "/usr/local/miniconda/lib/python3.7/site-packages/nipype/pipeline/engine/utils.py", line 498, in modify_paths
    raise IOError('File %s not found' % out)
OSError: File /projects/adapt_lab/shared/TPOT/bids_data/derivatives/working/fmriprep_wf/single_subject_TPOT025_wf/func_preproc_ses_1_task_video_wf/func_derivatives_wf/raw_sources/sub-TPOT025/ses-1/func/sub-TPOT025_ses-1_task-video_bold.nii.gz not found
"""

The above exception was the direct cause of the following exception:

Traceback (most recent call last):
  File "/usr/local/miniconda/lib/python3.7/concurrent/futures/_base.py", line 324, in _invoke_callbacks
    callback(self)
  File "/usr/local/miniconda/lib/python3.7/site-packages/nipype/pipeline/plugins/multiproc.py", line 151, in _async_callback
    result = args.result()
  File "/usr/local/miniconda/lib/python3.7/concurrent/futures/_base.py", line 425, in result
    return self.__get_result()
  File "/usr/local/miniconda/lib/python3.7/concurrent/futures/_base.py", line 384, in __get_result
    raise self._exception
OSError: File /projects/adapt_lab/shared/TPOT/bids_data/derivatives/working/fmriprep_wf/single_subject_TPOT025_wf/func_preproc_ses_1_task_video_wf/func_derivatives_wf/raw_sources/sub-TPOT025/ses-1/func/sub-TPOT025_ses-1_task-video_bold.nii.gz not found
exception calling callback for <Future at 0x2aaad2fee898 state=finished raised OSError>
concurrent.futures.process._RemoteTraceback: 
"""
Traceback (most recent call last):
  File "/usr/local/miniconda/lib/python3.7/site-packages/nipype/pipeline/plugins/multiproc.py", line 69, in run_node
    result['result'] = node.run(updatehash=updatehash)
  File "/usr/local/miniconda/lib/python3.7/site-packages/nipype/pipeline/engine/nodes.py", line 487, in run
    self, report_type='postexec', is_mapnode=isinstance(self, MapNode))
  File "/usr/local/miniconda/lib/python3.7/site-packages/nipype/pipeline/engine/utils.py", line 149, in write_report
    result = node.result  # Locally cache result
  File "/usr/local/miniconda/lib/python3.7/site-packages/nipype/pipeline/engine/nodes.py", line 197, in result
    return _load_resultfile(self.output_dir(), self.name)[0]
  File "/usr/local/miniconda/lib/python3.7/site-packages/nipype/pipeline/engine/utils.py", line 359, in load_resultfile
    basedir=path).items()):
  File "/usr/local/miniconda/lib/python3.7/site-packages/nipype/pipeline/engine/utils.py", line 478, in modify_paths
    val, relative=relative, basedir=basedir)
  File "/usr/local/miniconda/lib/python3.7/site-packages/nipype/pipeline/engine/utils.py", line 484, in modify_paths
    modify_paths(val, relative=relative, basedir=basedir))
  File "/usr/local/miniconda/lib/python3.7/site-packages/nipype/pipeline/engine/utils.py", line 498, in modify_paths
    raise IOError('File %s not found' % out)
OSError: File /projects/adapt_lab/shared/TPOT/bids_data/derivatives/working/fmriprep_wf/single_subject_TPOT025_wf/anat_preproc_wf/anat_derivatives_wf/raw_sources/sub-TPOT025/ses-1/anat/sub-TPOT025_ses-1_T1w.nii.gz not found

During handling of the above exception, another exception occurred:

Traceback (most recent call last):
  File "/usr/local/miniconda/lib/python3.7/concurrent/futures/process.py", line 232, in _process_worker
    r = call_item.fn(*call_item.args, **call_item.kwargs)
  File "/usr/local/miniconda/lib/python3.7/site-packages/nipype/pipeline/plugins/multiproc.py", line 72, in run_node
    result['result'] = node.result
  File "/usr/local/miniconda/lib/python3.7/site-packages/nipype/pipeline/engine/nodes.py", line 197, in result
    return _load_resultfile(self.output_dir(), self.name)[0]
  File "/usr/local/miniconda/lib/python3.7/site-packages/nipype/pipeline/engine/utils.py", line 359, in load_resultfile
    basedir=path).items()):
  File "/usr/local/miniconda/lib/python3.7/site-packages/nipype/pipeline/engine/utils.py", line 478, in modify_paths
    val, relative=relative, basedir=basedir)
  File "/usr/local/miniconda/lib/python3.7/site-packages/nipype/pipeline/engine/utils.py", line 484, in modify_paths
    modify_paths(val, relative=relative, basedir=basedir))
  File "/usr/local/miniconda/lib/python3.7/site-packages/nipype/pipeline/engine/utils.py", line 498, in modify_paths
    raise IOError('File %s not found' % out)
OSError: File /projects/adapt_lab/shared/TPOT/bids_data/derivatives/working/fmriprep_wf/single_subject_TPOT025_wf/anat_preproc_wf/anat_derivatives_wf/raw_sources/sub-TPOT025/ses-1/anat/sub-TPOT025_ses-1_T1w.nii.gz not found
"""

The above exception was the direct cause of the following exception:

Traceback (most recent call last):
  File "/usr/local/miniconda/lib/python3.7/concurrent/futures/_base.py", line 324, in _invoke_callbacks
    callback(self)
  File "/usr/local/miniconda/lib/python3.7/site-packages/nipype/pipeline/plugins/multiproc.py", line 151, in _async_callback
    result = args.result()
  File "/usr/local/miniconda/lib/python3.7/concurrent/futures/_base.py", line 425, in result
    return self.__get_result()
  File "/usr/local/miniconda/lib/python3.7/concurrent/futures/_base.py", line 384, in __get_result
    raise self._exception
OSError: File /projects/adapt_lab/shared/TPOT/bids_data/derivatives/working/fmriprep_wf/single_subject_TPOT025_wf/anat_preproc_wf/anat_derivatives_wf/raw_sources/sub-TPOT025/ses-1/anat/sub-TPOT025_ses-1_T1w.nii.gz not found
slurmstepd: error: *** JOB 9546197 ON n017 CANCELLED AT 2019-07-07T18:22:58 DUE TO TIME LIMIT ***
