<<<<<<< HEAD
<<<<<<< HEAD
exception calling callback for <Future at 0x2aaad80a9710 state=finished raised OSError>
concurrent.futures.process._RemoteTraceback: 
"""
Traceback (most recent call last):
  File "/usr/local/miniconda/lib/python3.7/site-packages/nipype/pipeline/plugins/multiproc.py", line 69, in run_node
    result['result'] = node.run(updatehash=updatehash)
  File "/usr/local/miniconda/lib/python3.7/site-packages/nipype/pipeline/engine/nodes.py", line 487, in run
    self, report_type='postexec', is_mapnode=isinstance(self, MapNode))
  File "/usr/local/miniconda/lib/python3.7/site-packages/nipype/pipeline/engine/utils.py", line 149, in write_report
    result = node.result  # Locally cache result
  File "/usr/local/miniconda/lib/python3.7/site-packages/nipype/pipeline/engine/nodes.py", line 197, in result
    return _load_resultfile(self.output_dir(), self.name)[0]
  File "/usr/local/miniconda/lib/python3.7/site-packages/nipype/pipeline/engine/utils.py", line 359, in load_resultfile
    basedir=path).items()):
  File "/usr/local/miniconda/lib/python3.7/site-packages/nipype/pipeline/engine/utils.py", line 478, in modify_paths
    val, relative=relative, basedir=basedir)
  File "/usr/local/miniconda/lib/python3.7/site-packages/nipype/pipeline/engine/utils.py", line 484, in modify_paths
    modify_paths(val, relative=relative, basedir=basedir))
  File "/usr/local/miniconda/lib/python3.7/site-packages/nipype/pipeline/engine/utils.py", line 498, in modify_paths
    raise IOError('File %s not found' % out)
OSError: File /projects/adapt_lab/shared/TPOT/bids_data/derivatives/working_test/fmriprep_wf/single_subject_TPOT002_wf/func_preproc_ses_1_task_affect_acq_2_wf/func_derivatives_wf/raw_sources/sub-TPOT002/ses-1/func/sub-TPOT002_ses-1_task-affect_acq-2_bold.nii.gz not found

During handling of the above exception, another exception occurred:

Traceback (most recent call last):
  File "/usr/local/miniconda/lib/python3.7/concurrent/futures/process.py", line 232, in _process_worker
    r = call_item.fn(*call_item.args, **call_item.kwargs)
  File "/usr/local/miniconda/lib/python3.7/site-packages/nipype/pipeline/plugins/multiproc.py", line 72, in run_node
    result['result'] = node.result
  File "/usr/local/miniconda/lib/python3.7/site-packages/nipype/pipeline/engine/nodes.py", line 197, in result
    return _load_resultfile(self.output_dir(), self.name)[0]
  File "/usr/local/miniconda/lib/python3.7/site-packages/nipype/pipeline/engine/utils.py", line 359, in load_resultfile
    basedir=path).items()):
  File "/usr/local/miniconda/lib/python3.7/site-packages/nipype/pipeline/engine/utils.py", line 478, in modify_paths
    val, relative=relative, basedir=basedir)
  File "/usr/local/miniconda/lib/python3.7/site-packages/nipype/pipeline/engine/utils.py", line 484, in modify_paths
    modify_paths(val, relative=relative, basedir=basedir))
  File "/usr/local/miniconda/lib/python3.7/site-packages/nipype/pipeline/engine/utils.py", line 498, in modify_paths
    raise IOError('File %s not found' % out)
OSError: File /projects/adapt_lab/shared/TPOT/bids_data/derivatives/working_test/fmriprep_wf/single_subject_TPOT002_wf/func_preproc_ses_1_task_affect_acq_2_wf/func_derivatives_wf/raw_sources/sub-TPOT002/ses-1/func/sub-TPOT002_ses-1_task-affect_acq-2_bold.nii.gz not found
"""

The above exception was the direct cause of the following exception:

Traceback (most recent call last):
  File "/usr/local/miniconda/lib/python3.7/concurrent/futures/_base.py", line 324, in _invoke_callbacks
    callback(self)
  File "/usr/local/miniconda/lib/python3.7/site-packages/nipype/pipeline/plugins/multiproc.py", line 151, in _async_callback
    result = args.result()
  File "/usr/local/miniconda/lib/python3.7/concurrent/futures/_base.py", line 425, in result
    return self.__get_result()
  File "/usr/local/miniconda/lib/python3.7/concurrent/futures/_base.py", line 384, in __get_result
    raise self._exception
OSError: File /projects/adapt_lab/shared/TPOT/bids_data/derivatives/working_test/fmriprep_wf/single_subject_TPOT002_wf/func_preproc_ses_1_task_affect_acq_2_wf/func_derivatives_wf/raw_sources/sub-TPOT002/ses-1/func/sub-TPOT002_ses-1_task-affect_acq-2_bold.nii.gz not found
exception calling callback for <Future at 0x2aaad827b390 state=finished raised OSError>
concurrent.futures.process._RemoteTraceback: 
"""
Traceback (most recent call last):
  File "/usr/local/miniconda/lib/python3.7/site-packages/nipype/pipeline/plugins/multiproc.py", line 69, in run_node
    result['result'] = node.run(updatehash=updatehash)
  File "/usr/local/miniconda/lib/python3.7/site-packages/nipype/pipeline/engine/nodes.py", line 487, in run
    self, report_type='postexec', is_mapnode=isinstance(self, MapNode))
  File "/usr/local/miniconda/lib/python3.7/site-packages/nipype/pipeline/engine/utils.py", line 149, in write_report
    result = node.result  # Locally cache result
  File "/usr/local/miniconda/lib/python3.7/site-packages/nipype/pipeline/engine/nodes.py", line 197, in result
    return _load_resultfile(self.output_dir(), self.name)[0]
  File "/usr/local/miniconda/lib/python3.7/site-packages/nipype/pipeline/engine/utils.py", line 359, in load_resultfile
    basedir=path).items()):
  File "/usr/local/miniconda/lib/python3.7/site-packages/nipype/pipeline/engine/utils.py", line 478, in modify_paths
    val, relative=relative, basedir=basedir)
  File "/usr/local/miniconda/lib/python3.7/site-packages/nipype/pipeline/engine/utils.py", line 484, in modify_paths
    modify_paths(val, relative=relative, basedir=basedir))
  File "/usr/local/miniconda/lib/python3.7/site-packages/nipype/pipeline/engine/utils.py", line 498, in modify_paths
    raise IOError('File %s not found' % out)
OSError: File /projects/adapt_lab/shared/TPOT/bids_data/derivatives/working_test/fmriprep_wf/single_subject_TPOT002_wf/func_preproc_ses_1_task_affect_acq_1_wf/func_derivatives_wf/raw_sources/sub-TPOT002/ses-1/func/sub-TPOT002_ses-1_task-affect_acq-1_bold.nii.gz not found

During handling of the above exception, another exception occurred:

Traceback (most recent call last):
  File "/usr/local/miniconda/lib/python3.7/concurrent/futures/process.py", line 232, in _process_worker
    r = call_item.fn(*call_item.args, **call_item.kwargs)
  File "/usr/local/miniconda/lib/python3.7/site-packages/nipype/pipeline/plugins/multiproc.py", line 72, in run_node
    result['result'] = node.result
  File "/usr/local/miniconda/lib/python3.7/site-packages/nipype/pipeline/engine/nodes.py", line 197, in result
    return _load_resultfile(self.output_dir(), self.name)[0]
  File "/usr/local/miniconda/lib/python3.7/site-packages/nipype/pipeline/engine/utils.py", line 359, in load_resultfile
    basedir=path).items()):
  File "/usr/local/miniconda/lib/python3.7/site-packages/nipype/pipeline/engine/utils.py", line 478, in modify_paths
    val, relative=relative, basedir=basedir)
  File "/usr/local/miniconda/lib/python3.7/site-packages/nipype/pipeline/engine/utils.py", line 484, in modify_paths
    modify_paths(val, relative=relative, basedir=basedir))
  File "/usr/local/miniconda/lib/python3.7/site-packages/nipype/pipeline/engine/utils.py", line 498, in modify_paths
    raise IOError('File %s not found' % out)
OSError: File /projects/adapt_lab/shared/TPOT/bids_data/derivatives/working_test/fmriprep_wf/single_subject_TPOT002_wf/func_preproc_ses_1_task_affect_acq_1_wf/func_derivatives_wf/raw_sources/sub-TPOT002/ses-1/func/sub-TPOT002_ses-1_task-affect_acq-1_bold.nii.gz not found
"""

The above exception was the direct cause of the following exception:

Traceback (most recent call last):
  File "/usr/local/miniconda/lib/python3.7/concurrent/futures/_base.py", line 324, in _invoke_callbacks
    callback(self)
  File "/usr/local/miniconda/lib/python3.7/site-packages/nipype/pipeline/plugins/multiproc.py", line 151, in _async_callback
    result = args.result()
  File "/usr/local/miniconda/lib/python3.7/concurrent/futures/_base.py", line 425, in result
    return self.__get_result()
  File "/usr/local/miniconda/lib/python3.7/concurrent/futures/_base.py", line 384, in __get_result
    raise self._exception
OSError: File /projects/adapt_lab/shared/TPOT/bids_data/derivatives/working_test/fmriprep_wf/single_subject_TPOT002_wf/func_preproc_ses_1_task_affect_acq_1_wf/func_derivatives_wf/raw_sources/sub-TPOT002/ses-1/func/sub-TPOT002_ses-1_task-affect_acq-1_bold.nii.gz not found
exception calling callback for <Future at 0x2aaad80c6f28 state=finished raised OSError>
concurrent.futures.process._RemoteTraceback: 
"""
Traceback (most recent call last):
  File "/usr/local/miniconda/lib/python3.7/site-packages/nipype/pipeline/plugins/multiproc.py", line 69, in run_node
    result['result'] = node.run(updatehash=updatehash)
  File "/usr/local/miniconda/lib/python3.7/site-packages/nipype/pipeline/engine/nodes.py", line 487, in run
    self, report_type='postexec', is_mapnode=isinstance(self, MapNode))
  File "/usr/local/miniconda/lib/python3.7/site-packages/nipype/pipeline/engine/utils.py", line 149, in write_report
    result = node.result  # Locally cache result
  File "/usr/local/miniconda/lib/python3.7/site-packages/nipype/pipeline/engine/nodes.py", line 197, in result
    return _load_resultfile(self.output_dir(), self.name)[0]
  File "/usr/local/miniconda/lib/python3.7/site-packages/nipype/pipeline/engine/utils.py", line 359, in load_resultfile
    basedir=path).items()):
  File "/usr/local/miniconda/lib/python3.7/site-packages/nipype/pipeline/engine/utils.py", line 478, in modify_paths
    val, relative=relative, basedir=basedir)
  File "/usr/local/miniconda/lib/python3.7/site-packages/nipype/pipeline/engine/utils.py", line 484, in modify_paths
    modify_paths(val, relative=relative, basedir=basedir))
  File "/usr/local/miniconda/lib/python3.7/site-packages/nipype/pipeline/engine/utils.py", line 498, in modify_paths
    raise IOError('File %s not found' % out)
OSError: File /projects/adapt_lab/shared/TPOT/bids_data/derivatives/working_test/fmriprep_wf/single_subject_TPOT002_wf/anat_preproc_wf/anat_derivatives_wf/raw_sources/sub-TPOT002/ses-1/anat/sub-TPOT002_ses-1_T1w.nii.gz not found

During handling of the above exception, another exception occurred:

Traceback (most recent call last):
  File "/usr/local/miniconda/lib/python3.7/concurrent/futures/process.py", line 232, in _process_worker
    r = call_item.fn(*call_item.args, **call_item.kwargs)
  File "/usr/local/miniconda/lib/python3.7/site-packages/nipype/pipeline/plugins/multiproc.py", line 72, in run_node
    result['result'] = node.result
  File "/usr/local/miniconda/lib/python3.7/site-packages/nipype/pipeline/engine/nodes.py", line 197, in result
    return _load_resultfile(self.output_dir(), self.name)[0]
  File "/usr/local/miniconda/lib/python3.7/site-packages/nipype/pipeline/engine/utils.py", line 359, in load_resultfile
    basedir=path).items()):
  File "/usr/local/miniconda/lib/python3.7/site-packages/nipype/pipeline/engine/utils.py", line 478, in modify_paths
    val, relative=relative, basedir=basedir)
  File "/usr/local/miniconda/lib/python3.7/site-packages/nipype/pipeline/engine/utils.py", line 484, in modify_paths
    modify_paths(val, relative=relative, basedir=basedir))
  File "/usr/local/miniconda/lib/python3.7/site-packages/nipype/pipeline/engine/utils.py", line 498, in modify_paths
    raise IOError('File %s not found' % out)
OSError: File /projects/adapt_lab/shared/TPOT/bids_data/derivatives/working_test/fmriprep_wf/single_subject_TPOT002_wf/anat_preproc_wf/anat_derivatives_wf/raw_sources/sub-TPOT002/ses-1/anat/sub-TPOT002_ses-1_T1w.nii.gz not found
"""

The above exception was the direct cause of the following exception:

Traceback (most recent call last):
  File "/usr/local/miniconda/lib/python3.7/concurrent/futures/_base.py", line 324, in _invoke_callbacks
    callback(self)
  File "/usr/local/miniconda/lib/python3.7/site-packages/nipype/pipeline/plugins/multiproc.py", line 151, in _async_callback
    result = args.result()
  File "/usr/local/miniconda/lib/python3.7/concurrent/futures/_base.py", line 425, in result
    return self.__get_result()
  File "/usr/local/miniconda/lib/python3.7/concurrent/futures/_base.py", line 384, in __get_result
    raise self._exception
OSError: File /projects/adapt_lab/shared/TPOT/bids_data/derivatives/working_test/fmriprep_wf/single_subject_TPOT002_wf/anat_preproc_wf/anat_derivatives_wf/raw_sources/sub-TPOT002/ses-1/anat/sub-TPOT002_ses-1_T1w.nii.gz not found
=======
=======
>>>>>>> fb75bef41d8b97d2200b2fd2911bc7ccda523792
Process Process-2:
Traceback (most recent call last):
  File "/usr/local/miniconda/lib/python3.7/multiprocessing/process.py", line 297, in _bootstrap
    self.run()
  File "/usr/local/miniconda/lib/python3.7/multiprocessing/process.py", line 99, in run
    self._target(*self._args, **self._kwargs)
  File "/usr/local/miniconda/lib/python3.7/site-packages/fmriprep/cli/run.py", line 651, in build_workflow
    work_dir=str(work_dir),
  File "/usr/local/miniconda/lib/python3.7/site-packages/fmriprep/workflows/base.py", line 259, in init_fmriprep_wf
    use_syn=use_syn,
  File "/usr/local/miniconda/lib/python3.7/site-packages/fmriprep/workflows/base.py", line 474, in init_single_subject_wf
    subject_id, task_id if task_id else '<all>'))
Exception: No BOLD images found for participant TPOT002 and task affect. All workflows require BOLD images.
<<<<<<< HEAD
>>>>>>> fb75bef41d8b97d2200b2fd2911bc7ccda523792
=======
>>>>>>> fb75bef41d8b97d2200b2fd2911bc7ccda523792
