FATAL ERROR: CALL_AND_RETRY_LAST Allocation failed - JavaScript heap out of memory
 1: 0x8dc1c0 node::Abort() [bids-validator]
 2: 0x8dc20c  [bids-validator]
 3: 0xad60ae v8::Utils::ReportOOMFailure(v8::internal::Isolate*, char const*, bool) [bids-validator]
 4: 0xad62e4 v8::internal::V8::FatalProcessOutOfMemory(v8::internal::Isolate*, char const*, bool) [bids-validator]
 5: 0xec3972  [bids-validator]
 6: 0xed318f v8::internal::Heap::AllocateRawWithRetryOrFail(int, v8::internal::AllocationSpace, v8::internal::AllocationAlignment) [bids-validator]
 7: 0xe9c1e6 v8::internal::Factory::AllocateRawArray(int, v8::internal::PretenureFlag) [bids-validator]
 8: 0xe9ca6a v8::internal::Factory::NewFixedArrayWithFiller(v8::internal::Heap::RootListIndex, int, v8::internal::Object*, v8::internal::PretenureFlag) [bids-validator]
 9: 0xe9cb10 v8::internal::Handle<v8::internal::FixedArray> v8::internal::Factory::NewFixedArrayWithMap<v8::internal::FixedArray>(v8::internal::Heap::RootListIndex, int, v8::internal::PretenureFlag) [bids-validator]
10: 0xfdc029 v8::internal::HashTable<v8::internal::NameDictionary, v8::internal::NameDictionaryShape>::New(v8::internal::Isolate*, int, v8::internal::PretenureFlag, v8::internal::MinimumCapacity) [bids-validator]
11: 0x1000f22 v8::internal::BaseNameDictionary<v8::internal::NameDictionary, v8::internal::NameDictionaryShape>::EnsureCapacity(v8::internal::Handle<v8::internal::NameDictionary>, int) [bids-validator]
12: 0x10010f0 v8::internal::BaseNameDictionary<v8::internal::NameDictionary, v8::internal::NameDictionaryShape>::AddNoUpdateNextEnumerationIndex(v8::internal::Handle<v8::internal::NameDictionary>, v8::internal::Handle<v8::internal::Name>, v8::internal::Handle<v8::internal::Object>, v8::internal::PropertyDetails, int*) [bids-validator]
13: 0x100139b v8::internal::BaseNameDictionary<v8::internal::NameDictionary, v8::internal::NameDictionaryShape>::Add(v8::internal::Handle<v8::internal::NameDictionary>, v8::internal::Handle<v8::internal::Name>, v8::internal::Handle<v8::internal::Object>, v8::internal::PropertyDetails, int*) [bids-validator]
14: 0x1164158 v8::internal::Runtime_AddDictionaryProperty(int, v8::internal::Object**, v8::internal::Isolate*) [bids-validator]
15: 0x179a0a8dbe1d 
Traceback (most recent call last):
  File "/usr/local/miniconda/bin/fmriprep", line 10, in <module>
    sys.exit(main())
  File "/usr/local/miniconda/lib/python3.7/site-packages/fmriprep/cli/run.py", line 313, in main
    validate_input_dir(exec_env, opts.bids_dir, opts.participant_label)
  File "/usr/local/miniconda/lib/python3.7/site-packages/fmriprep/utils/bids.py", line 146, in validate_input_dir
    subprocess.check_call(['bids-validator', bids_dir, '-c', temp.name])
  File "/usr/local/miniconda/lib/python3.7/subprocess.py", line 341, in check_call
    raise CalledProcessError(retcode, cmd)
subprocess.CalledProcessError: Command '['bids-validator', PosixPath('/projects/adapt_lab/shared/TPOT/bids_data'), '-c', '/tmp/tmpxu6xa3pj']' died with <Signals.SIGABRT: 6>.
Sentry is attempting to send 0 pending error messages
Waiting up to 2.0 seconds
Press Ctrl-C to quit
(node:127746) UnhandledPromiseRejectionWarning: Error: ENOENT: no such file or directory, lstat '/projects/adapt_lab/shared/TPOT/bids_data/derivatives/working/fmriprep_wf/single_subject_TPOT064_wf/func_preproc_ses_1_task_affect_acq_2_wf/bold_bold_trans_wf/bold_transform/tmp-822_lkdu/mat2itk_pos-001_xfm-00087.txt'
    at Object.lstatSync (fs.js:841:3)
    at isDirectory (/usr/lib/node_modules/bids-validator/utils/files/readDir.js:130:23)
    at files.map.file (/usr/lib/node_modules/bids-validator/utils/files/readDir.js:116:9)
    at Array.map (<anonymous>)
    at getFiles (/usr/lib/node_modules/bids-validator/utils/files/readDir.js:99:9)
    at files.map.file (/usr/lib/node_modules/bids-validator/utils/files/readDir.js:117:7)
    at Array.map (<anonymous>)
    at getFiles (/usr/lib/node_modules/bids-validator/utils/files/readDir.js:99:9)
    at files.map.file (/usr/lib/node_modules/bids-validator/utils/files/readDir.js:117:7)
    at Array.map (<anonymous>)
(node:127746) UnhandledPromiseRejectionWarning: Unhandled promise rejection. This error originated either by throwing inside of an async function without a catch block, or by rejecting a promise which was not handled with .catch(). (rejection id: 1)
(node:127746) [DEP0018] DeprecationWarning: Unhandled promise rejections are deprecated. In the future, promise rejections that are not handled will terminate the Node.js process with a non-zero exit code.
The ``--output_space`` option has been deprecated in version 1.4.0. Your selection of spaces "T1w, template, fsaverage5, fsnative" will be inserted at the front of the ``--output-spaces`` argument list. Please update your scripts to use ``--output-spaces``.
exception calling callback for <Future at 0x2aaad348acf8 state=finished raised OSError>
concurrent.futures.process._RemoteTraceback: 
"""
Traceback (most recent call last):
  File "/usr/local/miniconda/lib/python3.7/site-packages/nipype/pipeline/plugins/multiproc.py", line 69, in run_node
    result['result'] = node.run(updatehash=updatehash)
  File "/usr/local/miniconda/lib/python3.7/site-packages/nipype/pipeline/engine/nodes.py", line 487, in run
    self, report_type='postexec', is_mapnode=isinstance(self, MapNode))
  File "/usr/local/miniconda/lib/python3.7/site-packages/nipype/pipeline/engine/utils.py", line 149, in write_report
    result = node.result  # Locally cache result
  File "/usr/local/miniconda/lib/python3.7/site-packages/nipype/pipeline/engine/nodes.py", line 197, in result
    return _load_resultfile(self.output_dir(), self.name)[0]
  File "/usr/local/miniconda/lib/python3.7/site-packages/nipype/pipeline/engine/utils.py", line 359, in load_resultfile
    basedir=path).items()):
  File "/usr/local/miniconda/lib/python3.7/site-packages/nipype/pipeline/engine/utils.py", line 478, in modify_paths
    val, relative=relative, basedir=basedir)
  File "/usr/local/miniconda/lib/python3.7/site-packages/nipype/pipeline/engine/utils.py", line 484, in modify_paths
    modify_paths(val, relative=relative, basedir=basedir))
  File "/usr/local/miniconda/lib/python3.7/site-packages/nipype/pipeline/engine/utils.py", line 498, in modify_paths
    raise IOError('File %s not found' % out)
OSError: File /projects/adapt_lab/shared/TPOT/bids_data/derivatives/working/fmriprep_wf/single_subject_TPOT156_wf/func_preproc_ses_1_task_video_run_01_wf/func_derivatives_wf/raw_sources/sub-TPOT156/ses-1/func/sub-TPOT156_ses-1_task-video_run-01_bold.nii.gz not found

During handling of the above exception, another exception occurred:

Traceback (most recent call last):
  File "/usr/local/miniconda/lib/python3.7/concurrent/futures/process.py", line 232, in _process_worker
    r = call_item.fn(*call_item.args, **call_item.kwargs)
  File "/usr/local/miniconda/lib/python3.7/site-packages/nipype/pipeline/plugins/multiproc.py", line 72, in run_node
    result['result'] = node.result
  File "/usr/local/miniconda/lib/python3.7/site-packages/nipype/pipeline/engine/nodes.py", line 197, in result
    return _load_resultfile(self.output_dir(), self.name)[0]
  File "/usr/local/miniconda/lib/python3.7/site-packages/nipype/pipeline/engine/utils.py", line 359, in load_resultfile
    basedir=path).items()):
  File "/usr/local/miniconda/lib/python3.7/site-packages/nipype/pipeline/engine/utils.py", line 478, in modify_paths
    val, relative=relative, basedir=basedir)
  File "/usr/local/miniconda/lib/python3.7/site-packages/nipype/pipeline/engine/utils.py", line 484, in modify_paths
    modify_paths(val, relative=relative, basedir=basedir))
  File "/usr/local/miniconda/lib/python3.7/site-packages/nipype/pipeline/engine/utils.py", line 498, in modify_paths
    raise IOError('File %s not found' % out)
OSError: File /projects/adapt_lab/shared/TPOT/bids_data/derivatives/working/fmriprep_wf/single_subject_TPOT156_wf/func_preproc_ses_1_task_video_run_01_wf/func_derivatives_wf/raw_sources/sub-TPOT156/ses-1/func/sub-TPOT156_ses-1_task-video_run-01_bold.nii.gz not found
"""

The above exception was the direct cause of the following exception:

Traceback (most recent call last):
  File "/usr/local/miniconda/lib/python3.7/concurrent/futures/_base.py", line 324, in _invoke_callbacks
    callback(self)
  File "/usr/local/miniconda/lib/python3.7/site-packages/nipype/pipeline/plugins/multiproc.py", line 151, in _async_callback
    result = args.result()
  File "/usr/local/miniconda/lib/python3.7/concurrent/futures/_base.py", line 425, in result
    return self.__get_result()
  File "/usr/local/miniconda/lib/python3.7/concurrent/futures/_base.py", line 384, in __get_result
    raise self._exception
OSError: File /projects/adapt_lab/shared/TPOT/bids_data/derivatives/working/fmriprep_wf/single_subject_TPOT156_wf/func_preproc_ses_1_task_video_run_01_wf/func_derivatives_wf/raw_sources/sub-TPOT156/ses-1/func/sub-TPOT156_ses-1_task-video_run-01_bold.nii.gz not found
exception calling callback for <Future at 0x2aaad36a5400 state=finished raised OSError>
concurrent.futures.process._RemoteTraceback: 
"""
Traceback (most recent call last):
  File "/usr/local/miniconda/lib/python3.7/site-packages/nipype/pipeline/plugins/multiproc.py", line 69, in run_node
    result['result'] = node.run(updatehash=updatehash)
  File "/usr/local/miniconda/lib/python3.7/site-packages/nipype/pipeline/engine/nodes.py", line 487, in run
    self, report_type='postexec', is_mapnode=isinstance(self, MapNode))
  File "/usr/local/miniconda/lib/python3.7/site-packages/nipype/pipeline/engine/utils.py", line 149, in write_report
    result = node.result  # Locally cache result
  File "/usr/local/miniconda/lib/python3.7/site-packages/nipype/pipeline/engine/nodes.py", line 197, in result
    return _load_resultfile(self.output_dir(), self.name)[0]
  File "/usr/local/miniconda/lib/python3.7/site-packages/nipype/pipeline/engine/utils.py", line 359, in load_resultfile
    basedir=path).items()):
  File "/usr/local/miniconda/lib/python3.7/site-packages/nipype/pipeline/engine/utils.py", line 478, in modify_paths
    val, relative=relative, basedir=basedir)
  File "/usr/local/miniconda/lib/python3.7/site-packages/nipype/pipeline/engine/utils.py", line 484, in modify_paths
    modify_paths(val, relative=relative, basedir=basedir))
  File "/usr/local/miniconda/lib/python3.7/site-packages/nipype/pipeline/engine/utils.py", line 498, in modify_paths
    raise IOError('File %s not found' % out)
OSError: File /projects/adapt_lab/shared/TPOT/bids_data/derivatives/working/fmriprep_wf/single_subject_TPOT156_wf/func_preproc_ses_1_task_video_run_02_wf/func_derivatives_wf/raw_sources/sub-TPOT156/ses-1/func/sub-TPOT156_ses-1_task-video_run-02_bold.nii.gz not found

During handling of the above exception, another exception occurred:

Traceback (most recent call last):
  File "/usr/local/miniconda/lib/python3.7/concurrent/futures/process.py", line 232, in _process_worker
    r = call_item.fn(*call_item.args, **call_item.kwargs)
  File "/usr/local/miniconda/lib/python3.7/site-packages/nipype/pipeline/plugins/multiproc.py", line 72, in run_node
    result['result'] = node.result
  File "/usr/local/miniconda/lib/python3.7/site-packages/nipype/pipeline/engine/nodes.py", line 197, in result
    return _load_resultfile(self.output_dir(), self.name)[0]
  File "/usr/local/miniconda/lib/python3.7/site-packages/nipype/pipeline/engine/utils.py", line 359, in load_resultfile
    basedir=path).items()):
  File "/usr/local/miniconda/lib/python3.7/site-packages/nipype/pipeline/engine/utils.py", line 478, in modify_paths
    val, relative=relative, basedir=basedir)
  File "/usr/local/miniconda/lib/python3.7/site-packages/nipype/pipeline/engine/utils.py", line 484, in modify_paths
    modify_paths(val, relative=relative, basedir=basedir))
  File "/usr/local/miniconda/lib/python3.7/site-packages/nipype/pipeline/engine/utils.py", line 498, in modify_paths
    raise IOError('File %s not found' % out)
OSError: File /projects/adapt_lab/shared/TPOT/bids_data/derivatives/working/fmriprep_wf/single_subject_TPOT156_wf/func_preproc_ses_1_task_video_run_02_wf/func_derivatives_wf/raw_sources/sub-TPOT156/ses-1/func/sub-TPOT156_ses-1_task-video_run-02_bold.nii.gz not found
"""

The above exception was the direct cause of the following exception:

Traceback (most recent call last):
  File "/usr/local/miniconda/lib/python3.7/concurrent/futures/_base.py", line 324, in _invoke_callbacks
    callback(self)
  File "/usr/local/miniconda/lib/python3.7/site-packages/nipype/pipeline/plugins/multiproc.py", line 151, in _async_callback
    result = args.result()
  File "/usr/local/miniconda/lib/python3.7/concurrent/futures/_base.py", line 425, in result
    return self.__get_result()
  File "/usr/local/miniconda/lib/python3.7/concurrent/futures/_base.py", line 384, in __get_result
    raise self._exception
OSError: File /projects/adapt_lab/shared/TPOT/bids_data/derivatives/working/fmriprep_wf/single_subject_TPOT156_wf/func_preproc_ses_1_task_video_run_02_wf/func_derivatives_wf/raw_sources/sub-TPOT156/ses-1/func/sub-TPOT156_ses-1_task-video_run-02_bold.nii.gz not found
slurmstepd: error: *** JOB 9546307 ON n052 CANCELLED AT 2019-07-07T19:41:28 DUE TO TIME LIMIT ***
