/usr/local/miniconda/lib/python3.7/site-packages/nipype/algorithms/confounds.py:1099: FutureWarning: `rcond` parameter will change to the default of machine precision times ``max(M, N)`` where M and N are the input matrix dimensions.
To use the future default and silence this warning we advise to pass `rcond=None`, to keep using the old, explicitly pass `rcond=-1`.
  betas = np.linalg.lstsq(X, data.T)[0]
/usr/local/miniconda/lib/python3.7/site-packages/matplotlib/contour.py:1173: UserWarning: No contour levels were found within the data range.
  warnings.warn("No contour levels were found"
/usr/local/miniconda/lib/python3.7/site-packages/matplotlib/contour.py:1173: UserWarning: No contour levels were found within the data range.
  warnings.warn("No contour levels were found"
/usr/local/miniconda/lib/python3.7/site-packages/matplotlib/contour.py:1173: UserWarning: No contour levels were found within the data range.
  warnings.warn("No contour levels were found"
/usr/local/miniconda/lib/python3.7/site-packages/matplotlib/contour.py:1173: UserWarning: No contour levels were found within the data range.
  warnings.warn("No contour levels were found"
/usr/local/miniconda/lib/python3.7/site-packages/nipype/algorithms/confounds.py:1099: FutureWarning: `rcond` parameter will change to the default of machine precision times ``max(M, N)`` where M and N are the input matrix dimensions.
To use the future default and silence this warning we advise to pass `rcond=None`, to keep using the old, explicitly pass `rcond=-1`.
  betas = np.linalg.lstsq(X, data.T)[0]
/usr/local/miniconda/lib/python3.7/site-packages/matplotlib/contour.py:1173: UserWarning: No contour levels were found within the data range.
  warnings.warn("No contour levels were found"
/usr/local/miniconda/lib/python3.7/site-packages/scipy/fftpack/basic.py:160: FutureWarning: Using a non-tuple sequence for multidimensional indexing is deprecated; use `arr[tuple(seq)]` instead of `arr[seq]`. In the future this will be interpreted as an array index, `arr[np.array(seq)]`, which will result either in an error or a different result.
  z[index] = x
/usr/local/miniconda/lib/python3.7/site-packages/scipy/fftpack/basic.py:160: FutureWarning: Using a non-tuple sequence for multidimensional indexing is deprecated; use `arr[tuple(seq)]` instead of `arr[seq]`. In the future this will be interpreted as an array index, `arr[np.array(seq)]`, which will result either in an error or a different result.
  z[index] = x
/usr/local/miniconda/lib/python3.7/site-packages/nipype/algorithms/confounds.py:1099: FutureWarning: `rcond` parameter will change to the default of machine precision times ``max(M, N)`` where M and N are the input matrix dimensions.
To use the future default and silence this warning we advise to pass `rcond=None`, to keep using the old, explicitly pass `rcond=-1`.
  betas = np.linalg.lstsq(X, data.T)[0]
/usr/local/miniconda/lib/python3.7/site-packages/matplotlib/contour.py:1173: UserWarning: No contour levels were found within the data range.
  warnings.warn("No contour levels were found"
/usr/local/miniconda/lib/python3.7/site-packages/nipype/algorithms/confounds.py:1099: FutureWarning: `rcond` parameter will change to the default of machine precision times ``max(M, N)`` where M and N are the input matrix dimensions.
To use the future default and silence this warning we advise to pass `rcond=None`, to keep using the old, explicitly pass `rcond=-1`.
  betas = np.linalg.lstsq(X, data.T)[0]
/usr/local/miniconda/lib/python3.7/site-packages/scipy/fftpack/basic.py:160: FutureWarning: Using a non-tuple sequence for multidimensional indexing is deprecated; use `arr[tuple(seq)]` instead of `arr[seq]`. In the future this will be interpreted as an array index, `arr[np.array(seq)]`, which will result either in an error or a different result.
  z[index] = x
/usr/local/miniconda/lib/python3.7/site-packages/nipype/algorithms/confounds.py:1099: FutureWarning: `rcond` parameter will change to the default of machine precision times ``max(M, N)`` where M and N are the input matrix dimensions.
To use the future default and silence this warning we advise to pass `rcond=None`, to keep using the old, explicitly pass `rcond=-1`.
  betas = np.linalg.lstsq(X, data.T)[0]
/usr/local/miniconda/lib/python3.7/site-packages/nipype/algorithms/confounds.py:1099: FutureWarning: `rcond` parameter will change to the default of machine precision times ``max(M, N)`` where M and N are the input matrix dimensions.
To use the future default and silence this warning we advise to pass `rcond=None`, to keep using the old, explicitly pass `rcond=-1`.
  betas = np.linalg.lstsq(X, data.T)[0]
/usr/local/miniconda/lib/python3.7/site-packages/matplotlib/contour.py:1173: UserWarning: No contour levels were found within the data range.
  warnings.warn("No contour levels were found"
/usr/local/miniconda/lib/python3.7/site-packages/matplotlib/contour.py:1173: UserWarning: No contour levels were found within the data range.
  warnings.warn("No contour levels were found"
/usr/local/miniconda/lib/python3.7/site-packages/matplotlib/contour.py:1173: UserWarning: No contour levels were found within the data range.
  warnings.warn("No contour levels were found"
/usr/local/miniconda/lib/python3.7/site-packages/matplotlib/contour.py:1173: UserWarning: No contour levels were found within the data range.
  warnings.warn("No contour levels were found"
/usr/local/miniconda/lib/python3.7/site-packages/nipype/algorithms/confounds.py:1099: FutureWarning: `rcond` parameter will change to the default of machine precision times ``max(M, N)`` where M and N are the input matrix dimensions.
To use the future default and silence this warning we advise to pass `rcond=None`, to keep using the old, explicitly pass `rcond=-1`.
  betas = np.linalg.lstsq(X, data.T)[0]
/usr/local/miniconda/lib/python3.7/site-packages/nipype/algorithms/confounds.py:1099: FutureWarning: `rcond` parameter will change to the default of machine precision times ``max(M, N)`` where M and N are the input matrix dimensions.
To use the future default and silence this warning we advise to pass `rcond=None`, to keep using the old, explicitly pass `rcond=-1`.
  betas = np.linalg.lstsq(X, data.T)[0]
/usr/local/miniconda/lib/python3.7/site-packages/nilearn/image/resampling.py:510: UserWarning: Casting data from int32 to float32
  warnings.warn("Casting data from %s to %s" % (data.dtype.name, aux))
/usr/local/miniconda/lib/python3.7/site-packages/nilearn/image/resampling.py:510: UserWarning: Casting data from int32 to float32
  warnings.warn("Casting data from %s to %s" % (data.dtype.name, aux))
/usr/local/miniconda/lib/python3.7/site-packages/nilearn/image/resampling.py:510: UserWarning: Casting data from int32 to float32
  warnings.warn("Casting data from %s to %s" % (data.dtype.name, aux))
/usr/local/miniconda/lib/python3.7/site-packages/nipype/algorithms/confounds.py:1099: FutureWarning: `rcond` parameter will change to the default of machine precision times ``max(M, N)`` where M and N are the input matrix dimensions.
To use the future default and silence this warning we advise to pass `rcond=None`, to keep using the old, explicitly pass `rcond=-1`.
  betas = np.linalg.lstsq(X, data.T)[0]
/usr/local/miniconda/lib/python3.7/site-packages/scipy/fftpack/basic.py:160: FutureWarning: Using a non-tuple sequence for multidimensional indexing is deprecated; use `arr[tuple(seq)]` instead of `arr[seq]`. In the future this will be interpreted as an array index, `arr[np.array(seq)]`, which will result either in an error or a different result.
  z[index] = x
/usr/local/miniconda/lib/python3.7/site-packages/scipy/fftpack/basic.py:160: FutureWarning: Using a non-tuple sequence for multidimensional indexing is deprecated; use `arr[tuple(seq)]` instead of `arr[seq]`. In the future this will be interpreted as an array index, `arr[np.array(seq)]`, which will result either in an error or a different result.
  z[index] = x
/usr/local/miniconda/lib/python3.7/site-packages/nipype/algorithms/confounds.py:1099: FutureWarning: `rcond` parameter will change to the default of machine precision times ``max(M, N)`` where M and N are the input matrix dimensions.
To use the future default and silence this warning we advise to pass `rcond=None`, to keep using the old, explicitly pass `rcond=-1`.
  betas = np.linalg.lstsq(X, data.T)[0]
/usr/local/miniconda/lib/python3.7/site-packages/matplotlib/contour.py:1173: UserWarning: No contour levels were found within the data range.
  warnings.warn("No contour levels were found"
Error in atexit._run_exitfuncs:
Traceback (most recent call last):
  File "/usr/local/miniconda/lib/python3.7/concurrent/futures/process.py", line 101, in _python_exit
    thread_wakeup.wakeup()
  File "/usr/local/miniconda/lib/python3.7/concurrent/futures/process.py", line 89, in wakeup
    self._writer.send_bytes(b"")
  File "/usr/local/miniconda/lib/python3.7/multiprocessing/connection.py", line 183, in send_bytes
    self._check_closed()
  File "/usr/local/miniconda/lib/python3.7/multiprocessing/connection.py", line 136, in _check_closed
    raise OSError("handle is closed")
OSError: handle is closed
exception calling callback for <Future at 0x2aaad9363358 state=finished raised OSError>
concurrent.futures.process._RemoteTraceback: 
"""
Traceback (most recent call last):
  File "/usr/local/miniconda/lib/python3.7/site-packages/nipype/pipeline/plugins/multiproc.py", line 69, in run_node
    result['result'] = node.run(updatehash=updatehash)
  File "/usr/local/miniconda/lib/python3.7/site-packages/nipype/pipeline/engine/nodes.py", line 487, in run
    self, report_type='postexec', is_mapnode=isinstance(self, MapNode))
  File "/usr/local/miniconda/lib/python3.7/site-packages/nipype/pipeline/engine/utils.py", line 149, in write_report
    result = node.result  # Locally cache result
  File "/usr/local/miniconda/lib/python3.7/site-packages/nipype/pipeline/engine/nodes.py", line 197, in result
    return _load_resultfile(self.output_dir(), self.name)[0]
  File "/usr/local/miniconda/lib/python3.7/site-packages/nipype/pipeline/engine/utils.py", line 359, in load_resultfile
    basedir=path).items()):
  File "/usr/local/miniconda/lib/python3.7/site-packages/nipype/pipeline/engine/utils.py", line 478, in modify_paths
    val, relative=relative, basedir=basedir)
  File "/usr/local/miniconda/lib/python3.7/site-packages/nipype/pipeline/engine/utils.py", line 484, in modify_paths
    modify_paths(val, relative=relative, basedir=basedir))
  File "/usr/local/miniconda/lib/python3.7/site-packages/nipype/pipeline/engine/utils.py", line 498, in modify_paths
    raise IOError('File %s not found' % out)
OSError: File /projects/adapt_lab/shared/TPOT/bids_data/derivatives/working/fmriprep_wf/single_subject_TPOT013_wf/func_preproc_ses_1_task_video_run_01_wf/func_derivatives_wf/raw_sources/sub-TPOT013/ses-1/func/sub-TPOT013_ses-1_task-video_run-01_bold.nii.gz not found

During handling of the above exception, another exception occurred:

Traceback (most recent call last):
  File "/usr/local/miniconda/lib/python3.7/concurrent/futures/process.py", line 232, in _process_worker
    r = call_item.fn(*call_item.args, **call_item.kwargs)
  File "/usr/local/miniconda/lib/python3.7/site-packages/nipype/pipeline/plugins/multiproc.py", line 72, in run_node
    result['result'] = node.result
  File "/usr/local/miniconda/lib/python3.7/site-packages/nipype/pipeline/engine/nodes.py", line 197, in result
    return _load_resultfile(self.output_dir(), self.name)[0]
  File "/usr/local/miniconda/lib/python3.7/site-packages/nipype/pipeline/engine/utils.py", line 359, in load_resultfile
    basedir=path).items()):
  File "/usr/local/miniconda/lib/python3.7/site-packages/nipype/pipeline/engine/utils.py", line 478, in modify_paths
    val, relative=relative, basedir=basedir)
  File "/usr/local/miniconda/lib/python3.7/site-packages/nipype/pipeline/engine/utils.py", line 484, in modify_paths
    modify_paths(val, relative=relative, basedir=basedir))
  File "/usr/local/miniconda/lib/python3.7/site-packages/nipype/pipeline/engine/utils.py", line 498, in modify_paths
    raise IOError('File %s not found' % out)
OSError: File /projects/adapt_lab/shared/TPOT/bids_data/derivatives/working/fmriprep_wf/single_subject_TPOT013_wf/func_preproc_ses_1_task_video_run_01_wf/func_derivatives_wf/raw_sources/sub-TPOT013/ses-1/func/sub-TPOT013_ses-1_task-video_run-01_bold.nii.gz not found
"""

The above exception was the direct cause of the following exception:

Traceback (most recent call last):
  File "/usr/local/miniconda/lib/python3.7/concurrent/futures/_base.py", line 324, in _invoke_callbacks
    callback(self)
  File "/usr/local/miniconda/lib/python3.7/site-packages/nipype/pipeline/plugins/multiproc.py", line 151, in _async_callback
    result = args.result()
  File "/usr/local/miniconda/lib/python3.7/concurrent/futures/_base.py", line 425, in result
    return self.__get_result()
  File "/usr/local/miniconda/lib/python3.7/concurrent/futures/_base.py", line 384, in __get_result
    raise self._exception
OSError: File /projects/adapt_lab/shared/TPOT/bids_data/derivatives/working/fmriprep_wf/single_subject_TPOT013_wf/func_preproc_ses_1_task_video_run_01_wf/func_derivatives_wf/raw_sources/sub-TPOT013/ses-1/func/sub-TPOT013_ses-1_task-video_run-01_bold.nii.gz not found
exception calling callback for <Future at 0x2aaad96c1898 state=finished raised OSError>
concurrent.futures.process._RemoteTraceback: 
"""
Traceback (most recent call last):
  File "/usr/local/miniconda/lib/python3.7/site-packages/nipype/pipeline/plugins/multiproc.py", line 69, in run_node
    result['result'] = node.run(updatehash=updatehash)
  File "/usr/local/miniconda/lib/python3.7/site-packages/nipype/pipeline/engine/nodes.py", line 487, in run
    self, report_type='postexec', is_mapnode=isinstance(self, MapNode))
  File "/usr/local/miniconda/lib/python3.7/site-packages/nipype/pipeline/engine/utils.py", line 149, in write_report
    result = node.result  # Locally cache result
  File "/usr/local/miniconda/lib/python3.7/site-packages/nipype/pipeline/engine/nodes.py", line 197, in result
    return _load_resultfile(self.output_dir(), self.name)[0]
  File "/usr/local/miniconda/lib/python3.7/site-packages/nipype/pipeline/engine/utils.py", line 359, in load_resultfile
    basedir=path).items()):
  File "/usr/local/miniconda/lib/python3.7/site-packages/nipype/pipeline/engine/utils.py", line 478, in modify_paths
    val, relative=relative, basedir=basedir)
  File "/usr/local/miniconda/lib/python3.7/site-packages/nipype/pipeline/engine/utils.py", line 484, in modify_paths
    modify_paths(val, relative=relative, basedir=basedir))
  File "/usr/local/miniconda/lib/python3.7/site-packages/nipype/pipeline/engine/utils.py", line 498, in modify_paths
    raise IOError('File %s not found' % out)
OSError: File /projects/adapt_lab/shared/TPOT/bids_data/derivatives/working/fmriprep_wf/single_subject_TPOT013_wf/func_preproc_2_ses_1_task_video_wf/func_derivatives_wf/raw_sources/sub-TPOT013_2/ses-1/func/sub-TPOT013_2_ses-1_task-video_bold.nii.gz not found

During handling of the above exception, another exception occurred:

Traceback (most recent call last):
  File "/usr/local/miniconda/lib/python3.7/concurrent/futures/process.py", line 232, in _process_worker
    r = call_item.fn(*call_item.args, **call_item.kwargs)
  File "/usr/local/miniconda/lib/python3.7/site-packages/nipype/pipeline/plugins/multiproc.py", line 72, in run_node
    result['result'] = node.result
  File "/usr/local/miniconda/lib/python3.7/site-packages/nipype/pipeline/engine/nodes.py", line 197, in result
    return _load_resultfile(self.output_dir(), self.name)[0]
  File "/usr/local/miniconda/lib/python3.7/site-packages/nipype/pipeline/engine/utils.py", line 359, in load_resultfile
    basedir=path).items()):
  File "/usr/local/miniconda/lib/python3.7/site-packages/nipype/pipeline/engine/utils.py", line 478, in modify_paths
    val, relative=relative, basedir=basedir)
  File "/usr/local/miniconda/lib/python3.7/site-packages/nipype/pipeline/engine/utils.py", line 484, in modify_paths
    modify_paths(val, relative=relative, basedir=basedir))
  File "/usr/local/miniconda/lib/python3.7/site-packages/nipype/pipeline/engine/utils.py", line 498, in modify_paths
    raise IOError('File %s not found' % out)
OSError: File /projects/adapt_lab/shared/TPOT/bids_data/derivatives/working/fmriprep_wf/single_subject_TPOT013_wf/func_preproc_2_ses_1_task_video_wf/func_derivatives_wf/raw_sources/sub-TPOT013_2/ses-1/func/sub-TPOT013_2_ses-1_task-video_bold.nii.gz not found
"""

The above exception was the direct cause of the following exception:

Traceback (most recent call last):
  File "/usr/local/miniconda/lib/python3.7/concurrent/futures/_base.py", line 324, in _invoke_callbacks
    callback(self)
  File "/usr/local/miniconda/lib/python3.7/site-packages/nipype/pipeline/plugins/multiproc.py", line 151, in _async_callback
    result = args.result()
  File "/usr/local/miniconda/lib/python3.7/concurrent/futures/_base.py", line 425, in result
    return self.__get_result()
  File "/usr/local/miniconda/lib/python3.7/concurrent/futures/_base.py", line 384, in __get_result
    raise self._exception
OSError: File /projects/adapt_lab/shared/TPOT/bids_data/derivatives/working/fmriprep_wf/single_subject_TPOT013_wf/func_preproc_2_ses_1_task_video_wf/func_derivatives_wf/raw_sources/sub-TPOT013_2/ses-1/func/sub-TPOT013_2_ses-1_task-video_bold.nii.gz not found
exception calling callback for <Future at 0x2aaad9693978 state=finished raised OSError>
concurrent.futures.process._RemoteTraceback: 
"""
Traceback (most recent call last):
  File "/usr/local/miniconda/lib/python3.7/site-packages/nipype/pipeline/plugins/multiproc.py", line 69, in run_node
    result['result'] = node.run(updatehash=updatehash)
  File "/usr/local/miniconda/lib/python3.7/site-packages/nipype/pipeline/engine/nodes.py", line 487, in run
    self, report_type='postexec', is_mapnode=isinstance(self, MapNode))
  File "/usr/local/miniconda/lib/python3.7/site-packages/nipype/pipeline/engine/utils.py", line 149, in write_report
    result = node.result  # Locally cache result
  File "/usr/local/miniconda/lib/python3.7/site-packages/nipype/pipeline/engine/nodes.py", line 197, in result
    return _load_resultfile(self.output_dir(), self.name)[0]
  File "/usr/local/miniconda/lib/python3.7/site-packages/nipype/pipeline/engine/utils.py", line 359, in load_resultfile
    basedir=path).items()):
  File "/usr/local/miniconda/lib/python3.7/site-packages/nipype/pipeline/engine/utils.py", line 478, in modify_paths
    val, relative=relative, basedir=basedir)
  File "/usr/local/miniconda/lib/python3.7/site-packages/nipype/pipeline/engine/utils.py", line 484, in modify_paths
    modify_paths(val, relative=relative, basedir=basedir))
  File "/usr/local/miniconda/lib/python3.7/site-packages/nipype/pipeline/engine/utils.py", line 498, in modify_paths
    raise IOError('File %s not found' % out)
OSError: File /projects/adapt_lab/shared/TPOT/bids_data/derivatives/working/fmriprep_wf/single_subject_TPOT013_wf/func_preproc_ses_1_task_video_run_02_wf/func_derivatives_wf/raw_sources/sub-TPOT013/ses-1/func/sub-TPOT013_ses-1_task-video_run-02_bold.nii.gz not found

During handling of the above exception, another exception occurred:

Traceback (most recent call last):
  File "/usr/local/miniconda/lib/python3.7/concurrent/futures/process.py", line 232, in _process_worker
    r = call_item.fn(*call_item.args, **call_item.kwargs)
  File "/usr/local/miniconda/lib/python3.7/site-packages/nipype/pipeline/plugins/multiproc.py", line 72, in run_node
    result['result'] = node.result
  File "/usr/local/miniconda/lib/python3.7/site-packages/nipype/pipeline/engine/nodes.py", line 197, in result
    return _load_resultfile(self.output_dir(), self.name)[0]
  File "/usr/local/miniconda/lib/python3.7/site-packages/nipype/pipeline/engine/utils.py", line 359, in load_resultfile
    basedir=path).items()):
  File "/usr/local/miniconda/lib/python3.7/site-packages/nipype/pipeline/engine/utils.py", line 478, in modify_paths
    val, relative=relative, basedir=basedir)
  File "/usr/local/miniconda/lib/python3.7/site-packages/nipype/pipeline/engine/utils.py", line 484, in modify_paths
    modify_paths(val, relative=relative, basedir=basedir))
  File "/usr/local/miniconda/lib/python3.7/site-packages/nipype/pipeline/engine/utils.py", line 498, in modify_paths
    raise IOError('File %s not found' % out)
OSError: File /projects/adapt_lab/shared/TPOT/bids_data/derivatives/working/fmriprep_wf/single_subject_TPOT013_wf/func_preproc_ses_1_task_video_run_02_wf/func_derivatives_wf/raw_sources/sub-TPOT013/ses-1/func/sub-TPOT013_ses-1_task-video_run-02_bold.nii.gz not found
"""

The above exception was the direct cause of the following exception:

Traceback (most recent call last):
  File "/usr/local/miniconda/lib/python3.7/concurrent/futures/_base.py", line 324, in _invoke_callbacks
    callback(self)
  File "/usr/local/miniconda/lib/python3.7/site-packages/nipype/pipeline/plugins/multiproc.py", line 151, in _async_callback
    result = args.result()
  File "/usr/local/miniconda/lib/python3.7/concurrent/futures/_base.py", line 425, in result
    return self.__get_result()
  File "/usr/local/miniconda/lib/python3.7/concurrent/futures/_base.py", line 384, in __get_result
    raise self._exception
OSError: File /projects/adapt_lab/shared/TPOT/bids_data/derivatives/working/fmriprep_wf/single_subject_TPOT013_wf/func_preproc_ses_1_task_video_run_02_wf/func_derivatives_wf/raw_sources/sub-TPOT013/ses-1/func/sub-TPOT013_ses-1_task-video_run-02_bold.nii.gz not found
slurmstepd: error: *** JOB 9624037 ON n047 CANCELLED AT 2019-07-30T14:25:28 ***
